Workbook

Sheet Resumen
A1: LATAM Social - avance del alcance completo
A2: Cifras al 2026-08-31. El estado de cada actividad se cambia en la hoja «Actividades».
A4: Avance global
A5: Medida | B5: Valor
A6: Avance por numero de actividades | B6: =IFERROR(SUMPRODUCT(Actividades!$H$2:$H$400,Actividades!$I$2:$I$400)/SUM(Actividades!$I$2:$I$400),0)
A7: Avance ponderado por esfuerzo estimado (semanas por ola) | B7: =IFERROR(SUMPRODUCT($B$22:$B$25,$C$22:$C$25)/SUM($C$22:$C$25),0)
A8: Actividades del alcance total | B8: =COUNTA(Actividades!$A$2:$A$400)
A9: Actividades que cuentan en el denominador | B9: =SUM(Actividades!$I$2:$I$400)
A11: Actividades por estado
A12: Estado | B12: Cuantas | C12: % del total
A13: Terminado | B13: =COUNTIF(Actividades!$G$2:$G$400,$A13) | C13: =IFERROR($B13/COUNTA(Actividades!$A$2:$A$400),0)
A14: En curso | B14: =COUNTIF(Actividades!$G$2:$G$400,$A14) | C14: =IFERROR($B14/COUNTA(Actividades!$A$2:$A$400),0)
A15: Pendiente | B15: =COUNTIF(Actividades!$G$2:$G$400,$A15) | C15: =IFERROR($B15/COUNTA(Actividades!$A$2:$A$400),0)
A16: Bloqueado | B16: =COUNTIF(Actividades!$G$2:$G$400,$A16) | C16: =IFERROR($B16/COUNTA(Actividades!$A$2:$A$400),0)
A17: Aplazado | B17: =COUNTIF(Actividades!$G$2:$G$400,$A17) | C17: =IFERROR($B17/COUNTA(Actividades!$A$2:$A$400),0)
A18: No aplica | B18: =COUNTIF(Actividades!$G$2:$G$400,$A18) | C18: =IFERROR($B18/COUNTA(Actividades!$A$2:$A$400),0)
A20: Avance por ola
A21: Ola | B21: Avance | C21: Semanas est. | D21: Actividades | E21: Terminadas
A22: Ola 0 - Fundaciones | B22: =IFERROR(SUMPRODUCT((Actividades!$B$2:$B$400=$A22)*Actividades!$H$2:$H$400*Actividades!$I$2:$I$400)/SUMPRODUCT((Actividades!$B$2:$B$400=$A22)*Actividades!$I$2:$I$400),0) | C22: 8.5 | D22: =COUNTIF(Actividades!$B$2:$B$400,$A22) | E22: =SUMPRODUCT((Actividades!$B$2:$B$400=$A22)*(Actividades!$G$2:$G$400="Terminado"))
A23: Ola 1 - MVP: operar sin Excel | B23: =IFERROR(SUMPRODUCT((Actividades!$B$2:$B$400=$A23)*Actividades!$H$2:$H$400*Actividades!$I$2:$I$400)/SUMPRODUCT((Actividades!$B$2:$B$400=$A23)*Actividades!$I$2:$I$400),0) | C23: 12 | D23: =COUNTIF(Actividades!$B$2:$B$400,$A23) | E23: =SUMPRODUCT((Actividades!$B$2:$B$400=$A23)*(Actividades!$G$2:$G$400="Terminado"))
A24: Ola 2 - Escalar comercialmente | B24: =IFERROR(SUMPRODUCT((Actividades!$B$2:$B$400=$A24)*Actividades!$H$2:$H$400*Actividades!$I$2:$I$400)/SUMPRODUCT((Actividades!$B$2:$B$400=$A24)*Actividades!$I$2:$I$400),0) | C24: 14 | D24: =COUNTIF(Actividades!$B$2:$B$400,$A24) | E24: =SUMPRODUCT((Actividades!$B$2:$B$400=$A24)*(Actividades!$G$2:$G$400="Terminado"))
A25: Ola 3 - Internacionalizar y endurecer | B25: =IFERROR(SUMPRODUCT((Actividades!$B$2:$B$400=$A25)*Actividades!$H$2:$H$400*Actividades!$I$2:$I$400)/SUMPRODUCT((Actividades!$B$2:$B$400=$A25)*Actividades!$I$2:$I$400),0) | C25: 10 | D25: =COUNTIF(Actividades!$B$2:$B$400,$A25) | E25: =SUMPRODUCT((Actividades!$B$2:$B$400=$A25)*(Actividades!$G$2:$G$400="Terminado"))
A27: Avance por fase
A28: Fase | B28: Nombre | C28: Avance | D28: Actividades | E28: Terminadas
A29: F0 | B29: Discovery | C29: =IFERROR(SUMPRODUCT((Actividades!$C$2:$C$400=$A29)*Actividades!$H$2:$H$400*Actividades!$I$2:$I$400)/SUMPRODUCT((Actividades!$C$2:$C$400=$A29)*Actividades!$I$2:$I$400),0) | D29: =COUNTIF(Actividades!$C$2:$C$400,$A29) | E29: =SUMPRODUCT((Actividades!$C$2:$C$400=$A29)*(Actividades!$G$2:$G$400="Terminado"))
A30: F1 | B30: Arquitectura y esqueleto | C30: =IFERROR(SUMPRODUCT((Actividades!$C$2:$C$400=$A30)*Actividades!$H$2:$H$400*Actividades!$I$2:$I$400)/SUMPRODUCT((Actividades!$C$2:$C$400=$A30)*Actividades!$I$2:$I$400),0) | D30: =COUNTIF(Actividades!$C$2:$C$400,$A30) | E30: =SUMPRODUCT((Actividades!$C$2:$C$400=$A30)*(Actividades!$G$2:$G$400="Terminado"))
A31: F2 | B31: Modelo de datos | C31: =IFERROR(SUMPRODUCT((Actividades!$C$2:$C$400=$A31)*Actividades!$H$2:$H$400*Actividades!$I$2:$I$400)/SUMPRODUCT((Actividades!$C$2:$C$400=$A31)*Actividades!$I$2:$I$400),0) | D31: =COUNTIF(Actividades!$C$2:$C$400,$A31) | E31: =SUMPRODUCT((Actividades!$C$2:$C$400=$A31)*(Actividades!$G$2:$G$400="Terminado"))
A32: F3 | B32: Design System y UX | C32: =IFERROR(SUMPRODUCT((Actividades!$C$2:$C$400=$A32)*Actividades!$H$2:$H$400*Actividades!$I$2:$I$400)/SUMPRODUCT((Actividades!$C$2:$C$400=$A32)*Actividades!$I$2:$I$400),0) | D32: =COUNTIF(Actividades!$C$2:$C$400,$A32) | E32: =SUMPRODUCT((Actividades!$C$2:$C$400=$A32)*(Actividades!$G$2:$G$400="Terminado"))
A33: F4 | B33: Core tecnico | C33: =IFERROR(SUMPRODUCT((Actividades!$C$2:$C$400=$A33)*Actividades!$H$2:$H$400*Actividades!$I$2:$I$400)/SUMPRODUCT((Actividades!$C$2:$C$400=$A33)*Actividades!$I$2:$I$400),0) | D33: =COUNTIF(Actividades!$C$2:$C$400,$A33) | E33: =SUMPRODUCT((Actividades!$C$2:$C$400=$A33)*(Actividades!$G$2:$G$400="Terminado"))
A34: F5 | B34: Adquisicion de creadores | C34: =IFERROR(SUMPRODUCT((Actividades!$C$2:$C$400=$A34)*Actividades!$H$2:$H$400*Actividades!$I$2:$I$400)/SUMPRODUCT((Actividades!$C$2:$C$400=$A34)*Actividades!$I$2:$I$400),0) | D34: =COUNTIF(Actividades!$C$2:$C$400,$A34) | E34: =SUMPRODUCT((Actividades!$C$2:$C$400=$A34)*(Actividades!$G$2:$G$400="Terminado"))
A35: F6 | B35: Portal del creador | C35: =IFERROR(SUMPRODUCT((Actividades!$C$2:$C$400=$A35)*Actividades!$H$2:$H$400*Actividades!$I$2:$I$400)/SUMPRODUCT((Actividades!$C$2:$C$400=$A35)*Actividades!$I$2:$I$400),0) | D35: =COUNTIF(Actividades!$C$2:$C$400,$A35) | E35: =SUMPRODUCT((Actividades!$C$2:$C$400=$A35)*(Actividades!$G$2:$G$400="Terminado"))
A36: F7 | B36: Motor de campana | C36: =IFERROR(SUMPRODUCT((Actividades!$C$2:$C$400=$A36)*Actividades!$H$2:$H$400*Actividades!$I$2:$I$400)/SUMPRODUCT((Actividades!$C$2:$C$400=$A36)*Actividades!$I$2:$I$400),0) | D36: =COUNTIF(Actividades!$C$2:$C$400,$A36) | E36: =SUMPRODUCT((Actividades!$C$2:$C$400=$A36)*(Actividades!$G$2:$G$400="Terminado"))
A37: F8 | B37: Contenido, revision y evidencia | C37: =IFERROR(SUMPRODUCT((Actividades!$C$2:$C$400=$A37)*Actividades!$H$2:$H$400*Actividades!$I$2:$I$400)/SUMPRODUCT((Actividades!$C$2:$C$400=$A37)*Actividades!$I$2:$I$400),0) | D37: =COUNTIF(Actividades!$C$2:$C$400,$A37) | E37: =SUMPRODUCT((Actividades!$C$2:$C$400=$A37)*(Actividades!$G$2:$G$400="Terminado"))
A38: F9 | B38: Finanzas | C38: =IFERROR(SUMPRODUCT((Actividades!$C$2:$C$400=$A38)*Actividades!$H$2:$H$400*Actividades!$I$2:$I$400)/SUMPRODUCT((Actividades!$C$2:$C$400=$A38)*Actividades!$I$2:$I$400),0) | D38: =COUNTIF(Actividades!$C$2:$C$400,$A38) | E38: =SUMPRODUCT((Actividades!$C$2:$C$400=$A38)*(Actividades!$G$2:$G$400="Terminado"))
A39: F10 | B39: Medicion y reportes | C39: =IFERROR(SUMPRODUCT((Actividades!$C$2:$C$400=$A39)*Actividades!$H$2:$H$400*Actividades!$I$2:$I$400)/SUMPRODUCT((Actividades!$C$2:$C$400=$A39)*Actividades!$I$2:$I$400),0) | D39: =COUNTIF(Actividades!$C$2:$C$400,$A39) | E39: =SUMPRODUCT((Actividades!$C$2:$C$400=$A39)*(Actividades!$G$2:$G$400="Terminado"))
A40: F11 | B40: Adquisicion de marcas y CRM | C40: =IFERROR(SUMPRODUCT((Actividades!$C$2:$C$400=$A40)*Actividades!$H$2:$H$400*Actividades!$I$2:$I$400)/SUMPRODUCT((Actividades!$C$2:$C$400=$A40)*Actividades!$I$2:$I$400),0) | D40: =COUNTIF(Actividades!$C$2:$C$400,$A40) | E40: =SUMPRODUCT((Actividades!$C$2:$C$400=$A40)*(Actividades!$G$2:$G$400="Terminado"))
... A46: F17 | B46: Produccion | C46: =IFERROR(SUMPRODUCT((Actividades!$C$2:$C$400=$A46)*Actividades!$H$2:$H$400*Actividades!$I$2:$I$400)/SUMPRODUCT((Actividades!$C$2:$C$400=$A46)*Actividades!$I$2:$I$400),0) | D46: =COUNTIF(Actividades!$C$2:$C$400,$A46) | E46: =SUMPRODUCT((Actividades!$C$2:$C$400=$A46)*(Actividades!$G$2:$G$400="Terminado"))
A48: Como leer esto
A49: - El primer numero cuenta ACTIVIDADES, no semanas. Las que quedan son de media mas grandes que las hechas: finanzas, integraciones y los dos portales son fases enteras sin empezar.
A50: - El segundo numero pondera cada ola por su estimacion de esfuerzo del propio roadmap, y es el mas honesto de los dos.
...

Sheet Config
A1: Estados y su peso en el avance
A2: Estado | B2: Peso | C2: Cuenta en el total | D2: Que significa
A3: Terminado | B3: 1 | C3: 1 | D3: Entregado, verificado y con su documento de iteracion cerrado.
A4: En curso | B4: 0.5 | C4: 1 | D4: Hay trabajo hecho y demostrable, pero la actividad no esta completa. Cuenta como medio.
A5: Pendiente | B5: 0 | C5: 1 | D5: No empezada.
A6: Bloqueado | B6: 0 | C6: 1 | D6: No se puede avanzar sin una decision externa (contador, abogado, proveedor).
A7: Aplazado | B7: 0 | C7: 0 | D7: Movida a proposito a otro momento del plan. NO cuenta en el denominador para no contarla dos veces.
A8: No aplica | B8: 0 | C8: 0 | D8: Descartada del alcance. No cuenta en el denominador.
A11: Esfuerzo estimado por ola (docs/04-ROADMAP, punto medio del rango)
A12: Ola | B12: Semanas | C12: Rango original
A13: Ola 0 - Fundaciones | B13: 8.5 | C13: 7 a 10 semanas
A14: Ola 1 - MVP: operar sin Excel | B14: 12 | C14: 10 a 14 semanas
A15: Ola 2 - Escalar comercialmente | B15: 14 | C15: 12 a 16 semanas
A16: Ola 3 - Internacionalizar y endurecer | B16: 10 | C16: 8 a 12 semanas
A19: Estas semanas son para 2 desarrolladores a tiempo completo. Con 1 solo, el propio roadmap dice que hay que multiplicar por 1,7.

Sheet Actividades
A1: ID | B1: Ola | C1: Fase | D1: Nombre de fase | E1: It. | F1: Actividad | G1: Estado | H1: Avance | I1: Cuenta | J1: Notas y evidencia
A2: 1 | B2: Ola 0 - Fundaciones | C2: F0 | D2: Discovery | E2: 0.1 | F2: Definicion de producto, actores, dominios, modulos, procesos, arquitectura, roadmap, decision log, business rules, DoD | G2: Terminado | H2: =IFERROR(INDEX(Config!$B$3:$B$8,MATCH($G2,Config!$A$3:$A$8,0)),0) | I2: =IFERROR(INDEX(Config!$C$3:$C$8,MATCH($G2,Config!$A$3:$A$8,0)),0) | J2: 18 documentos en docs/. DEC-001 a DEC-098 registradas
A3: 2 | B3: Ola 0 - Fundaciones | C3: F1 | D3: Arquitectura y esqueleto | E3: 1.1 | F3: Stack, hosting y proveedores definitivos (SMTP, storage, error tracking) | G3: En curso | H3: =IFERROR(INDEX(Config!$B$3:$B$8,MATCH($G3,Config!$A$3:$A$8,0)),0) | I3: =IFERROR(INDEX(Config!$C$3:$C$8,MATCH($G3,Config!$A$3:$A$8,0)),0) | J3: Stack cerrado (Laravel 12 / PHP 8.3 / MySQL-Percona). Hosting: solicitud redactada en tools/solicitud-hosting-mysql8.md, sin contratar. SMTP, S3 y error tracking sin proveedor
A4: 3 | B4: Ola 0 - Fundaciones | C4: F1 | D4: Arquitectura y esqueleto | E4: 1.2 | F4: Esqueleto del proyecto, estructura de modulos, Composer, .env.example | G4: Terminado | H4: =IFERROR(INDEX(Config!$B$3:$B$8,MATCH($G4,Config!$A$3:$A$8,0)),0) | I4: =IFERROR(INDEX(Config!$C$3:$C$8,MATCH($G4,Config!$A$3:$A$8,0)),0) | J4: 13 contextos + Shared. .env.example en el repo
A5: 4 | B5: Ola 0 - Fundaciones | C5: F1 | D5: Arquitectura y esqueleto | E5: 1.3 | F5: CI: lint, analisis estatico, pruebas, Deptrac (fronteras de modulos) | G5: Terminado | H5: =IFERROR(INDEX(Config!$B$3:$B$8,MATCH($G5,Config!$A$3:$A$8,0)),0) | I5: =IFERROR(INDEX(Config!$C$3:$C$8,MATCH($G5,Config!$A$3:$A$8,0)),0) | J5: Seis puertas en verde: Pint, PHPStan, Deptrac, PHPUnit, vigencias, nombres entre capas. .github/workflows/ci.yml
A6: 5 | B6: Ola 0 - Fundaciones | C6: F1 | D6: Arquitectura y esqueleto | E6: 1.4 | F6: Convenciones: naming, commits, ramas, PR template, ADRs | G6: Terminado | H6: =IFERROR(INDEX(Config!$B$3:$B$8,MATCH($G6,Config!$A$3:$A$8,0)),0) | I6: =IFERROR(INDEX(Config!$C$3:$C$8,MATCH($G6,Config!$A$3:$A$8,0)),0) | J6: CONTRIBUTING.md + docs/03-ARCHITECTURE.md. Las decisiones van al DECISION LOG (DEC-nnn), no a ADRs sueltos
A7: 6 | B7: Ola 0 - Fundaciones | C7: F2 | D7: Modelo de datos | E7: 2.1 | F7: Entidades y glosario de negocio | G7: Terminado | H7: =IFERROR(INDEX(Config!$B$3:$B$8,MATCH($G7,Config!$A$3:$A$8,0)),0) | I7: =IFERROR(INDEX(Config!$C$3:$C$8,MATCH($G7,Config!$A$3:$A$8,0)),0) | J7: docs/fase-2/2.1
A8: 7 | B8: Ola 0 - Fundaciones | C8: F2 | D8: Modelo de datos | E8: 2.2 | F8: Relaciones y cardinalidades | G8: Terminado | H8: =IFERROR(INDEX(Config!$B$3:$B$8,MATCH($G8,Config!$A$3:$A$8,0)),0) | I8: =IFERROR(INDEX(Config!$C$3:$C$8,MATCH($G8,Config!$A$3:$A$8,0)),0) | J8: docs/fase-2/2.2
A9: 8 | B9: Ola 0 - Fundaciones | C9: F2 | D9: Modelo de datos | E9: 2.3 | F9: Normalizacion y separacion aplicacion/creador, cliente/marca/contacto | G9: Terminado | H9: =IFERROR(INDEX(Config!$B$3:$B$8,MATCH($G9,Config!$A$3:$A$8,0)),0) | I9: =IFERROR(INDEX(Config!$C$3:$C$8,MATCH($G9,Config!$A$3:$A$8,0)),0) | J9: docs/fase-2/2.3. Incluye N-03, implementada en 7.3
A10: 9 | B10: Ola 0 - Fundaciones | C10: F2 | D10: Modelo de datos | E10: 2.4 | F10: Estados, transiciones e historicos | G10: Terminado | H10: =IFERROR(INDEX(Config!$B$3:$B$8,MATCH($G10,Config!$A$3:$A$8,0)),0) | I10: =IFERROR(INDEX(Config!$C$3:$C$8,MATCH($G10,Config!$A$3:$A$8,0)),0) | J10: docs/fase-2/2.4 y 2.5. Tabla status_transitions + maquinas de estado en codigo
A11: 10 | B11: Ola 0 - Fundaciones | C11: F2 | D11: Modelo de datos | E11: 2.5 | F11: Finanzas: ledger, monedas, impuestos, retenciones, facturacion | G11: Terminado | H11: =IFERROR(INDEX(Config!$B$3:$B$8,MATCH($G11,Config!$A$3:$A$8,0)),0) | I11: =IFERROR(INDEX(Config!$C$3:$C$8,MATCH($G11,Config!$A$3:$A$8,0)),0) | J11: docs/fase-2/2.13 y 2.15. DISENO cerrado; la construccion es F9
A12: 11 | B12: Ola 0 - Fundaciones | C12: F2 | D12: Modelo de datos | E12: 2.6 | F12: Multi-entidad legal: marcas de plataforma, entidades legales, cobertura con vigencia, series, cuentas | G12: Terminado | H12: =IFERROR(INDEX(Config!$B$3:$B$8,MATCH($G12,Config!$A$3:$A$8,0)),0) | I12: =IFERROR(INDEX(Config!$C$3:$C$8,MATCH($G12,Config!$A$3:$A$8,0)),0) | J12: docs/fase-2/2.10. Construido en 4.5b
A13: 12 | B13: Ola 0 - Fundaciones | C13: F2 | D13: Modelo de datos | E13: 2.7 | F13: Integraciones: proveedores, conexiones, asignaciones con vigencia, credenciales, webhooks, trazas | G13: Pendiente | H13: =IFERROR(INDEX(Config!$B$3:$B$8,MATCH($G13,Config!$A$3:$A$8,0)),0) | I13: =IFERROR(INDEX(Config!$C$3:$C$8,MATCH($G13,Config!$A$3:$A$8,0)),0) | J13: Sin documento y sin tablas integration_*. Bloquea F4.6b y toda la F12
... A17: 16 | B17: Ola 0 - Fundaciones | C17: F2 | D17: Modelo de datos | E17: 2.11 | F17: Revision adversarial del modelo + ERD final | G17: Terminado | H17: =IFERROR(INDEX(Config!$B$3:$B$8,MATCH($G17,Config!$A$3:$A$8,0)),0) | I17: =IFERROR(INDEX(Config!$C$3:$C$8,MATCH($G17,Config!$A$3:$A$8,0)),0) | J17: Hecha. Dejo siete hallazgos, los siete cerrados (el ultimo, T-23). Falta publicar el ERD como imagen
A18: 17 | B18: Ola 0 - Fundaciones | C18: F3 | D18: Design System y UX | E18: 3.1 | F18: Journeys de los 6 perfiles | G18: Pendiente | H18: =IFERROR(INDEX(Config!$B$3:$B$8,MATCH($G18,Config!$A$3:$A$8,0)),0) | I18: =IFERROR(INDEX(Config!$C$3:$C$8,MATCH($G18,Config!$A$3:$A$8,0)),0)
A19: 18 | B19: Ola 0 - Fundaciones | C19: F3 | D19: Design System y UX | E19: 3.2 | F19: Tokens: color, tipografia, espaciado, radios, sombras, modo claro/oscuro | G19: Terminado | H19: =IFERROR(INDEX(Config!$B$3:$B$8,MATCH($G19,Config!$A$3:$A$8,0)),0) | I19: =IFERROR(INDEX(Config!$C$3:$C$8,MATCH($G19,Config!$A$3:$A$8,0)),0) | J19: Q-29/Q-30 respondidas (2026-08-30): la identidad visual se configura desde el admin (9.17). El kit de marca esta en marca/, pero el wordmark usa una tipografia de sistema y no una de diseno (T-71): en cuanto haya uno de verdad se sube desde la pantalla.
A20: 19 | B20: Ola 0 - Fundaciones | C20: F3 | D20: Design System y UX | E20: 3.3 | F20: Componentes base: botones, formularios, tablas, cards, badges, modales, tabs, alertas | G20: En curso | H20: =IFERROR(INDEX(Config!$B$3:$B$8,MATCH($G20,Config!$A$3:$A$8,0)),0) | I20: =IFERROR(INDEX(Config!$C$3:$C$8,MATCH($G20,Config!$A$3:$A$8,0)),0) | J20: Existen de facto en las plantillas del panel, sin catalogo ni documentacion
A21: 20 | B21: Ola 0 - Fundaciones | C21: F3 | D21: Design System y UX | E21: 3.4 | F21: Estados: vacio, carga, error, sin permisos, sin resultados | G21: En curso | H21: =IFERROR(INDEX(Config!$B$3:$B$8,MATCH($G21,Config!$A$3:$A$8,0)),0) | I21: =IFERROR(INDEX(Config!$C$3:$C$8,MATCH($G21,Config!$A$3:$A$8,0)),0) | J21: Vacio y sin permisos si (403 con motivo). Carga y error no estan sistematizados
A22: 21 | B22: Ola 0 - Fundaciones | C22: F3 | D22: Design System y UX | E22: 3.5 | F22: Wireframes de baja fidelidad de las 12 pantallas criticas | G22: Pendiente | H22: =IFERROR(INDEX(Config!$B$3:$B$8,MATCH($G22,Config!$A$3:$A$8,0)),0) | I22: =IFERROR(INDEX(Config!$C$3:$C$8,MATCH($G22,Config!$A$3:$A$8,0)),0) | J22: Se ha ido construyendo pantalla a pantalla sin wireframe previo
A23: 22 | B23: Ola 0 - Fundaciones | C23: F3 | D23: Design System y UX | E23: 3.6 | F23: Identidad diferenciada por portal | G23: Terminado | H23: =IFERROR(INDEX(Config!$B$3:$B$8,MATCH($G23,Config!$A$3:$A$8,0)),0) | I23: =IFERROR(INDEX(Config!$C$3:$C$8,MATCH($G23,Config!$A$3:$A$8,0)),0) | J23: Token de densidad por portal en design/tokens.css
A24: 23 | B24: Ola 0 - Fundaciones | C24: F3 | D24: Design System y UX | E24: 3.7 | F24: Sustituir assets del kit por los corregidos y publicar la guia de marca interna | G24: Pendiente | H24: =IFERROR(INDEX(Config!$B$3:$B$8,MATCH($G24,Config!$A$3:$A$8,0)),0) | I24: =IFERROR(INDEX(Config!$C$3:$C$8,MATCH($G24,Config!$A$3:$A$8,0)),0) | J24: Depende de Q-30 y Q-31
A25: 24 | B25: Ola 0 - Fundaciones | C25: F4 | D25: Core tecnico | E25: 4.1 | F25: Identidad: usuarios, login, logout, recuperacion, verificacion de email, sesiones | G25: Terminado | H25: =IFERROR(INDEX(Config!$B$3:$B$8,MATCH($G25,Config!$A$3:$A$8,0)),0) | I25: =IFERROR(INDEX(Config!$C$3:$C$8,MATCH($G25,Config!$A$3:$A$8,0)),0) | J25: docs/fase-5/5.9 y docs/fase-7/7.6b. DEC-113 a DEC-118 y DEC-126. Recuperacion por enlace, misma respuesta exista o no el correo, URL sin token. Desde 7.6b tampoco se teclea la del equipo (BR-SEC-004 cerrada). Falta la verificacion de correo
A26: 25 | B26: Ola 0 - Fundaciones | C26: F4 | D26: Core tecnico | E26: 4.2 | F26: RBAC: roles, permisos, politicas de recurso, pruebas de autorizacion negativas | G26: Terminado | H26: =IFERROR(INDEX(Config!$B$3:$B$8,MATCH($G26,Config!$A$3:$A$8,0)),0) | I26: =IFERROR(INDEX(Config!$C$3:$C$8,MATCH($G26,Config!$A$3:$A$8,0)),0) | J26: docs/fase-3/3.1. 127 permisos usados, todos existentes (puerta de nombres entre capas)
A27: 26 | B27: Ola 0 - Fundaciones | C27: F4 | D27: Core tecnico | E27: 4.3 | F27: Ambito de acceso externo: client_organization_id y creator_id por politica de recurso | G27: Pendiente | H27: =IFERROR(INDEX(Config!$B$3:$B$8,MATCH($G27,Config!$A$3:$A$8,0)),0) | I27: =IFERROR(INDEX(Config!$C$3:$C$8,MATCH($G27,Config!$A$3:$A$8,0)),0) | J27: No hay portales externos todavia. Llega con F6 y F13
A28: 27 | B28: Ola 0 - Fundaciones | C28: F4 | D28: Core tecnico | E28: 4.3b | F28: MFA/TOTP obligatorio para roles con permisos financieros (BR-SEC-005) | G28: Pendiente | H28: =IFERROR(INDEX(Config!$B$3:$B$8,MATCH($G28,Config!$A$3:$A$8,0)),0) | I28: =IFERROR(INDEX(Config!$C$3:$C$8,MATCH($G28,Config!$A$3:$A$8,0)),0) | J28: Barato ahora, caro de retrofitear. Deberia entrar antes de F9
A29: 28 | B29: Ola 0 - Fundaciones | C29: F4 | D29: Core tecnico | E29: 4.4 | F29: Auditoria append-only + activity log, con request_id | G29: Terminado | H29: =IFERROR(INDEX(Config!$B$3:$B$8,MATCH($G29,Config!$A$3:$A$8,0)),0) | I29: =IFERROR(INDEX(Config!$C$3:$C$8,MATCH($G29,Config!$A$3:$A$8,0)),0) | J29: docs/fase-3/3.2 y 3.3. Protegida por dos usuarios de base de datos (DEC-085): falta ejecutar los GRANT en produccion
A30: 29 | B30: Ola 0 - Fundaciones | C30: F4 | D30: Core tecnico | E30: 4.5 | F30: Catalogos maestros + seeders (paises, monedas, idiomas, redes, tipos de documento) | G30: Terminado | H30: =IFERROR(INDEX(Config!$B$3:$B$8,MATCH($G30,Config!$A$3:$A$8,0)),0) | I30: =IFERROR(INDEX(Config!$C$3:$C$8,MATCH($G30,Config!$A$3:$A$8,0)),0) | J30: CimientosSeeder + pantalla de catalogos
... A39: 38 | B39: Ola 0 - Fundaciones | C39: F4 | D39: Core tecnico | E39: 4.12 | F39: Layout de admin, navegacion, busqueda basica, tabla estandar con filtros/orden/paginacion | G39: Terminado | H39: =IFERROR(INDEX(Config!$B$3:$B$8,MATCH($G39,Config!$A$3:$A$8,0)),0) | I39: =IFERROR(INDEX(Config!$C$3:$C$8,MATCH($G39,Config!$A$3:$A$8,0)),0) | J39: layouts/panel + 21 plantillas. La busqueda global no existe; los listados filtran
A40: 39 | B40: Ola 0 - Fundaciones | C40: F4 | D40: Core tecnico | E40: 4.13 | F40: QA de fase + Phase Review Report | G40: Pendiente | H40: =IFERROR(INDEX(Config!$B$3:$B$8,MATCH($G40,Config!$A$3:$A$8,0)),0) | I40: =IFERROR(INDEX(Config!$C$3:$C$8,MATCH($G40,Config!$A$3:$A$8,0)),0)
A41: 40 | B41: Ola 1 - MVP: operar sin Excel | C41: F5 | D41: Adquisicion de creadores | E41: 5.1 | F41: Landing de creadores (responsive, SEO, consentimientos) | G41: Pendiente | H41: =IFERROR(INDEX(Config!$B$3:$B$8,MATCH($G41,Config!$A$3:$A$8,0)),0) | I41: =IFERROR(INDEX(Config!$C$3:$C$8,MATCH($G41,Config!$A$3:$A$8,0)),0) | J41: No hay ninguna ruta publica
A42: 41 | B42: Ola 1 - MVP: operar sin Excel | C42: F5 | D42: Adquisicion de creadores | E42: 5.2 | F42: Formulario de aplicacion multi-paso con guardado parcial | G42: Pendiente | H42: =IFERROR(INDEX(Config!$B$3:$B$8,MATCH($G42,Config!$A$3:$A$8,0)),0) | I42: =IFERROR(INDEX(Config!$C$3:$C$8,MATCH($G42,Config!$A$3:$A$8,0)),0) | J42: La tabla creator_applications existe; el formulario publico no
A43: 42 | B43: Ola 1 - MVP: operar sin Excel | C43: F5 | D43: Adquisicion de creadores | E43: 5.3 | F43: Cuentas sociales declaradas + metricas + evidencias | G43: Terminado | H43: =IFERROR(INDEX(Config!$B$3:$B$8,MATCH($G43,Config!$A$3:$A$8,0)),0) | I43: =IFERROR(INDEX(Config!$C$3:$C$8,MATCH($G43,Config!$A$3:$A$8,0)),0) | J43: docs/fase-3/3.7. Con verificacion y snapshots de metricas
A44: 43 | B44: Ola 1 - MVP: operar sin Excel | C44: F5 | D44: Adquisicion de creadores | E44: 5.4 | F44: Subida de archivos y capturas de insights | G44: En curso | H44: =IFERROR(INDEX(Config!$B$3:$B$8,MATCH($G44,Config!$A$3:$A$8,0)),0) | I44: =IFERROR(INDEX(Config!$C$3:$C$8,MATCH($G44,Config!$A$3:$A$8,0)),0) | J44: La subida existe para identidad; falta el flujo de insights de redes
A45: 44 | B45: Ola 1 - MVP: operar sin Excel | C45: F5 | D45: Adquisicion de creadores | E45: 5.5 | F45: Deteccion de duplicados y validaciones anti-basura (honeypot, rate limit, verificacion de email) | G45: En curso | H45: =IFERROR(INDEX(Config!$B$3:$B$8,MATCH($G45,Config!$A$3:$A$8,0)),0) | I45: =IFERROR(INDEX(Config!$C$3:$C$8,MATCH($G45,Config!$A$3:$A$8,0)),0) | J45: Duplicados: huellas de cuenta de pago con convergencia (4.10). Anti-basura publico: no, porque no hay formulario publico
A46: 45 | B46: Ola 1 - MVP: operar sin Excel | C46: F5 | D46: Adquisicion de creadores | E46: 5.6 | F46: Importacion masiva CSV/Excel con mapeo, previsualizacion, validacion, resumen y reversion | G46: En curso | H46: =IFERROR(INDEX(Config!$B$3:$B$8,MATCH($G46,Config!$A$3:$A$8,0)),0) | I46: =IFERROR(INDEX(Config!$C$3:$C$8,MATCH($G46,Config!$A$3:$A$8,0)),0) | J46: Plantilla CSV y guia escritas (tools/). El importador no esta construido
A47: 46 | B47: Ola 1 - MVP: operar sin Excel | C47: F5 | D47: Adquisicion de creadores | E47: 5.7 | F47: Bandeja de revision + ficha 360 + notas internas | G47: Terminado | H47: =IFERROR(INDEX(Config!$B$3:$B$8,MATCH($G47,Config!$A$3:$A$8,0)),0) | I47: =IFERROR(INDEX(Config!$C$3:$C$8,MATCH($G47,Config!$A$3:$A$8,0)),0) | J47: docs/fase-3/3.4. Rutas solicitudes.* y creadores.show
A48: 47 | B48: Ola 1 - MVP: operar sin Excel | C48: F5 | D48: Adquisicion de creadores | E48: 5.8 | F48: Maquina de estados + aprobar/rechazar/solicitar informacion con motivos tipificados | G48: Terminado | H48: =IFERROR(INDEX(Config!$B$3:$B$8,MATCH($G48,Config!$A$3:$A$8,0)),0) | I48: =IFERROR(INDEX(Config!$C$3:$C$8,MATCH($G48,Config!$A$3:$A$8,0)),0) | J48: docs/fase-3/3.4 y 3.5. Activacion con seis requisitos
A49: 48 | B49: Ola 1 - MVP: operar sin Excel | C49: F5 | D49: Adquisicion de creadores | E49: 5.9 | F49: Aprobacion -> creacion de usuario + enlace seguro de contrasena + emails | G49: Terminado | H49: =IFERROR(INDEX(Config!$B$3:$B$8,MATCH($G49,Config!$A$3:$A$8,0)),0) | I49: =IFERROR(INDEX(Config!$C$3:$C$8,MATCH($G49,Config!$A$3:$A$8,0)),0) | J49: docs/fase-5/5.9-ENLACE-DE-CONTRASENA.md. Crea la cuenta, escribe creators.user_id y manda el enlace de 72 h. La cuenta nace con una contrasena que no conoce nadie
A50: 49 | B50: Ola 1 - MVP: operar sin Excel | C50: F5 | D50: Adquisicion de creadores | E50: 5.10 | F50: Blacklist | G50: En curso | H50: =IFERROR(INDEX(Config!$B$3:$B$8,MATCH($G50,Config!$A$3:$A$8,0)),0) | I50: =IFERROR(INDEX(Config!$C$3:$C$8,MATCH($G50,Config!$A$3:$A$8,0)),0) | J50: El estado blacklisted existe en creadores y clientes. Falta la pantalla y el motivo tipificado
A51: 50 | B51: Ola 1 - MVP: operar sin Excel | C51: F5 | D51: Adquisicion de creadores | E51: 5.11 | F51: QA de fase + Phase Review Report | G51: Pendiente | H51: =IFERROR(INDEX(Config!$B$3:$B$8,MATCH($G51,Config!$A$3:$A$8,0)),0) | I51: =IFERROR(INDEX(Config!$C$3:$C$8,MATCH($G51,Config!$A$3:$A$8,0)),0)
...

Sheet Tareas
A1: Tareas técnicas y de gestión (T-XX). Nacen cuando algo se descubre roto o a medias y no se puede arreglar en el momento. Fuente: docs/05-DECISION-LOG.md. Las abiertas van arriba.
A2: ID | B2: Estado | C2: Prioridad | D2: Que hay que hacer | E2: Cuando hace falta | F2: Quien la desbloquea | G2: Detalle
A3: T-09 | B3: Abierta | C3: Critica | D3: Que un abogado revise el texto base de los terminos. | E3: Antes de la primera discusion real con un creador | F3: Tu abogado | G3: Ya NO bloquea nada (9.16): el sistema arranca con un texto de partida sembrado y publicado, se edita desde el admin, y los creadores se pueden activar hoy. Lo que queda es la revision juridica de ese texto, que la propia pantalla marca en rojo mientras no ocurra --review_status = sin_revisar-- y que ademas cuenta las once marcas [REVISAR] que el borrador lleva dentro. Los tres bloques que mas necesitan al abogado: menores de edad (hoy la aceptacion se registra a nombre del creador y no del tutor), propiedad intelectual del contenido --el sistema no modela licencia, exclusividad ni plazo de uso, y son el nucleo de un contrato de marketing de creadores-- y ley aplicable y fuero. Insumos en docs/legal/Insumos-terminos-creador.docx
A4: T-69 | B4: Abierta | C4: Critica | D4: Repasar toda decision anterior que fije un valor en el codigo, bajo DEC-190. | E4: Trabajo de fondo | F4: Equipo de desarrollo | G4: El principio de white label llego en 9.16 y hay noventa decisiones tomadas antes. Las que se sabe que hay que revisar: los 30 dias de plazo de pago (BR-FIN-012, hoy por creador pero con el 30 de fabrica en el codigo), el periodo de enfriamiento de un medio de pago (BR-FIN-006), las dos rondas incluidas (BR-CONTENT-003), el corte de 10 dias de una tasa rancia (DEC-160), los umbrales del buscador de creadores, y la marca de la plataforma. Ninguno esta mal hoy; lo que esta mal es que para cambiarlos haya que tocar codigo. Se hace por partes y con su iteracion, no de golpe
A5: T-29 | B5: Abierta | D5: Cinco iteraciones de la Fase 3 sin documento. | E5: Antes de que se olvide el porque | F5: Equipo de desarrollo | G5: 3.9 (tarifas), 3.11 (anulacion), 3.12 (no borrar), 3.13 (terminos) y 3.14 (rotacion de clave). Todas las demas iteraciones del proyecto tienen el suyo. El trabajo esta hecho y verificado por sus suites; lo que falta es el documento que explica por que, que es justo lo que no se puede reconstruir leyendo el codigo dentro de seis meses
A6: T-34 | B6: Abierta | D6: BR-CREATOR-012 dice menos de lo que el esquema implica. | E6: Al revisar docs/06 | F6: Equipo de desarrollo | G6: El texto habla solo de creadores CON TUTELA ACTIVA, y min_creator_age es una columna de campaigns que no menciona la tutela: aplicarla solo a los menores dejaria pasar a un creador de 20 anos en una campana de 21. En 7.4 se aplica a TODOS, y la edad minima efectiva es el maximo entre la de la campana y la de las categorias de la marca. Lo que hay que corregir es el texto de la regla, no el codigo
A7: T-35 | B7: Abierta | D7: El runbook de despliegue existe pero nadie lo ha ejecutado. | E7: Al primer despliegue | F7: Tu (primer despliegue) | G7: docs/18-RUNBOOK-DESPLIEGUE.md (2026-08-26) recoge por fin los pasos que vivian en conversaciones: los dos GRANT de DEC-085, las DOS lineas de cron --la de la cola y la del scheduler, que no son la misma y falta cualquiera de las dos rompe algo distinto--, el orden de despliegue y las comprobaciones posteriores. Escribirlo no lo ejecuta: sigue pendiente hacerlo en el servidor real y corregir el documento con lo que se descubra, porque un runbook que nadie ha seguido es una hipotesis
A8: T-37 | B8: Abierta | D8: VARBINARY faltaba en el reconocedor de tipos de generar-triggers.py y puede faltar algo mas. | E8: Antes de anadir un tipo de columna nuevo | F8: Equipo de desarrollo | G8: ^BINARY no casaba con VARBINARY(16): la columna no entraba en la lista y el CHECK que la nombraba se generaba como un disparador con el identificador suelto. Arreglado, y se vio porque MySQL grita; el hueco llevaba desde la Fase 2 en audit_logs.ip_address y creator_identity_verifications.ip_address, dos columnas que nunca habian aparecido en un CHECK. Lo que queda por hacer es la comprobacion que lo habria cazado antes: que el generador falle cuando una linea de una tabla parece definicion de columna y el reconocedor de tipos la descarta, en vez de seguir en silencio
A9: T-64 | B9: Abierta | D9: La matriz de permisos del seeder concede y no revoca nunca. | E9: Antes de la siguiente revocacion | F9: Equipo de desarrollo | G9: CimientosSeeder aplica los roles con updateOrInsert, asi que quitar una linea de la matriz no quita el permiso en ninguna base que ya lo tenga --produccion incluida-- y el permiso sigue puesto sin que nada lo diga. Se descubrio al revocar campaign.view_margin en 9.10a, y alli se resolvio con un DELETE explicito en la migracion; el problema es general y el siguiente «quitale ese permiso a ese rol» fallara igual. Hace falta decidir la forma: o la matriz se vuelve autoritativa --y entonces borra lo que no aparece, con el riesgo de tumbar concesiones hechas a mano-- o cada revocacion pasa por su migracion y eso se escribe donde se pueda encontrar
A10: T-65 | B10: Abierta | D10: 147 reglas del esquema siguen sin que nadie les pregunte nada. | E10: Trabajo de fondo | F10: Equipo de desarrollo | G10: Bajo de 167 a 147 al cubrir las veinte del camino del dinero (9.14). La mayor concentracion que queda esta en invoices (12), creator_tax_profiles (9) y creator_payment_methods (7): tablas de dinero y de datos sensibles de las Fases 2 y 3. Bajarlo es trabajo mecanico y medible, y el trinquete de MUDAS-BASE impide que suba mientras tanto. Cuidado con la forma facil de bajarlo mal: una asercion que admite OTRO motivo por la alternancia de porque() cuenta como cubierta y no ha preguntado nada --paso en esta misma iteracion con las dos reglas de payments--
A11: T-66 | B11: Abierta | D11: Los mensajes de las restricciones de la Fase 2 son genericos. | E11: Antes de que un usuario real vea un 45000 | F11: Equipo de desarrollo | G11: Dicen «Restriccion ck_ledger_sign incumplida», que en Percona 5.7 es literalmente lo que ve el usuario, mientras que las de la Fase 9 dicen una frase que explica que paso. Cambiar un mensaje exige recrear la restriccion --Restriccion::comprobacion() crea, no reemplaza-- asi que es su propia iteracion, con su migracion y su vuelta atras. Se descubrio al escribir 9.14, que tuvo que afirmar por NOMBRE en vez de por mensaje en las veinte reglas del dinero
A12: T-68 | B12: Abierta | D12: El registro de decisiones y 16-RESPUESTAS-NEGOCIO.md no dicen lo mismo sobre que preguntas siguen abiertas. | E12: Antes de volver a contar preguntas abiertas | F12: Equipo de desarrollo | G12: Doc 16 da por respondidas en su §1 varias preguntas tempranas --Q-05 a Q-28-- y en 05-DECISION-LOG.md hay filas de ese rango que siguen sin tachar. Las dos cosas pueden ser ciertas a la vez --la pregunta gorda contestada y un detalle de diseno abierto-- pero nadie puede saberlo leyendo, y el registro de decisiones es el que manda (§94). Salio al construir las pestanas de tareas y preguntas del Excel de avance, que es la primera vez que alguien las conto. Hay que repasar ese rango una por una y cerrar en el registro las que doc 16 ya contesto, o dejar escrito que queda de cada una
A13: T-70 | B13: Abierta | D13: 16-RESPUESTAS-NEGOCIO.md se quedo viejo: veintiuna preguntas se respondieron el 2026-08-30 y no estan alli. | E13: Antes de volver a citarlo | F13: Equipo de desarrollo | G13: El registro de decisiones ya las tiene cerradas una por una; aquel documento sigue contando quince respuestas de agosto. O se actualiza, o se marca como historico de la primera tanda y se dice que el registro manda. Relacionada con T-68
A14: T-71 | B14: Abierta | D14: El logotipo esta compuesto con una tipografia de sistema, no con una de diseno. | E14: Cuando haya un logotipo disenado | F14: Equipo de desarrollo | G14: marca/01_Logo_Horizontal.svg y 02_Logo_Vertical.svg llevan el texto vivo con font-family="DejaVu Sans", y los SVG de public/img/brand/ son los contornos de esa misma composicion. Funciona y se ve bien, pero el wordmark no esta disenado: esta escrito con la tipografia por defecto del sistema que lo genero. No es urgente --la plataforma opera igual-- y deja de ser un problema tecnico en cuanto 9.17 permita subirlo: el dia que haya un logotipo de verdad se sube desde el admin y ya. Salio al contestar Q-30
A15: T-10 | B15: Resuelta | D15: RESUELTA (2026-08-26, iteracion 4.13). — El aviso al creador cuando cambian sus datos fiscales o su medio de pago. | E15: — | F15: Equipo de desarrollo | G15: Cierra la mitad que faltaba de BR-CREATOR-007 (🔴): la aprobacion interna existia desde 3.6 y 3.8, la NOTIFICACION no --«la pantalla se lo recuerda al operador para que lo haga a mano», que es otra forma de decir que no se hacia--. 390 pruebas, siete mutaciones en rojo, las seis puertas en verde con Deptrac incluido: que el grafo siga acilico ES parte del resultado. Ver docs/fase-4/4.13-AVISO-DE-CAMBIO.md
A16: T-11 | B16: Resuelta | D16: *(hecho en 3.14)* Rotar APP_KEY invalida las huellas de las cuentas bancarias. Los números siguen siendo recuperables (Crypt conserva APP_PREVIOUS_KEYS), pero la huella es un HMAC con esa clave: tras una rotación, la detección de cuentas repetidas (DEC-065) deja de funcionar sobre las filas viejas. | E16: Antes de la primera rotación de clave | F16: Equipo de desarrollo | G16: Hace falta un comando que las recalcule. No es un problema hoy y sí lo será el día de la primera rotación
... A25: T-20 | B25: Resuelta | D25: CERRADA DEL TODO (2026-08-25, iteracion 4.10). — La primera mitad la resolvio DEC-083. | E25: — | F25: Equipo de desarrollo | G25: El resto era el 1062 del recalculo cuando dos filas del MISMO creador convergen: con la clave rotada, dos medios de la misma cuenta llevan huellas distintas, uq_cpm_open_account no los ve y los dos entran; al recalcular convergen y la transaccion se cae con un Duplicate entry en crudo, dejando el recalculo sin hacer. Y este choque no se absorbe: reintentar da la misma huella y choca igual. Es el lado opuesto de DEC-087 --el valor no lo eligio el sistema, lo eligio la realidad-- y la respuesta es contar, no recalcular: dos medios abiertos del mismo creador que son la misma cuenta, y cual sobrevive depende de cual esta verificado y si tiene pagos detras. Ahora se ve en la revision, antes de escribir nada, comparando el estado DESPUES del recalculo --mirar solo las pendientes entre si dejaria pasar el caso mas probable, una fila vieja y una nueva-- y solo sobre las filas ABIERTAS. El 1062 que sobreviva a la carrera se traduce con Choque::esDe. Ver docs/fase-4/4.10-CONVERGENCIA-DE-HUELLAS.md
A26: T-21 | B26: Resuelta | D26: RESUELTA (2026-08-25). — «Vigente» exige valid_from <= CURDATE() (DEC-084), y el mensaje de aprobacion distingue «aprobado y vigente» de «aprobado, todavia NO rige» | E26: — | F26: Equipo de desarrollo
A27: T-22 | B27: Resuelta | D27: RESUELTA (2026-08-25). — La guarda de solicitudes deja de filtrar por estado —las unicas se apoyan en identity_gate, que no lo mira— y el mensaje distingue un duplicado administrativo de una persona en lista negra. | E27: — | F27: Equipo de desarrollo | G27: La de redes sociales comprueba ademas las cuentas propias, que era el caso frecuente
A28: T-23 | B28: Resuelta | D28: RESUELTA (2026-08-25). — DEC-086: middleware en el grupo web, pantalla de cambio, y tres reglas que hacen que sirva —la nueva distinta de la actual, se pide la actual, y sin permiso—. | E28: — | F28: Equipo de desarrollo | G28: La marca que se escribia desde 3.1 por fin significa algo
A29: T-24 | B29: Resuelta | D29: RESUELTA (2026-08-25). — max(1, ...) en el config. | E29: — | F29: Equipo de desarrollo | G29: Un comentario que dice «esto no puede pasar» y no lo impide es una nota, no una regla
A30: T-25 | B30: Resuelta | D30: RESUELTA (2026-08-25). La suite de PHPUnit se ejecuto por primera vez. — 228 pruebas, 695 aserciones. | E30: — | F30: Equipo de desarrollo | G30: Seis iteraciones (4.1–4.5 y los ~23 arreglos de las revisiones) solo se habian comprobado con suites SQL y puertas estaticas. Unico fallo real: tests/Feature/ExampleTest.php, la prueba de ejemplo de Laravel que afirma que / devuelve 200 cuando Route::redirect('/', '/panel') devuelve 302. Llevaba roja desde 1.1 y nadie lo sabia porque nada la ejecutaba: la puerta pruebas existe, pero el CI se instalo este mismo dia. RutasTest dice en su propio docblock que la *sustituye* — se escribio el reemplazo y no se borro el original. Se borra
A31: T-26 | B31: Resuelta | D31: RESUELTA (2026-08-25). Verificado el verificador. — Que 228 pruebas nunca ejecutadas salgan verdes a la primera es sospechoso, asi que se comprobo con tres mutaciones. | E31: — | F31: Equipo de desarrollo | G31: Dos se detectaron por la prueba que dice detectarlas (Vigencia::puedeRelevar() sin normalizar fechas → VigenciaTest; different:actual fuera → CambioPasswordTest). La tercera sobrevivio: devolver el where('le.status','active') a Cobertura::abiertaEnPais() dejaba las quince pruebas de 4.5 en verde. La suite SQL si lo veia —el disparador de no-solapamiento rechaza el INSERT— pero ninguna prueba comprobaba que la capa PHP lo evita ANTES, o sea que el operador recibiria un 45000 en crudo. Se anadio la prueba 16, que con la mutacion se pone roja
A32: T-27 | B32: Resuelta | D32: RESUELTA (2026-08-25, iteracion 4.11). — tools/pruebas/4.11-concurrencia.sh: dos clientes de verdad contra el mismo motor, sin un solo sleep de sincronizacion. | E32: — | F32: Equipo de desarrollo | G32: B pone innodb_lock_wait_timeout=1 y se afirma el 1205: mientras A tenga el bloqueo, B falla siempre, tarde lo que tarde la maquina; si no lo tiene, pasa. Los dos resultados son deterministas. Para saber que una sesion ya ejecuto se usan cerrojos con nombre: escribir una marca y buscarla en la salida no funciona porque el cliente bufferiza, y un GET_LOCK no es transaccional --se ve desde fuera aunque quien lo tomo siga con su transaccion abierta-- y se pregunta con SQL. Demuestra en el motor lo que hasta hoy estaba deducido y no medido: que el UPDATE que baja al principal no toma ningun bloqueo cuando el puesto esta libre, que por eso los dos llegan al INSERT, y que con el bloqueo de la fila del cliente se ponen en fila antes de escribir. Lleva su propio contraejemplo (con el puesto OCUPADO si espera), sin el cual la primera asercion saldria verde aunque el aparato no funcionase. Bateria: 812 (MariaDB) y 802 (MySQL 8), cero fallidas. El CI no hubo que tocarlo: los tres bloques leen SUITES desde DEC-076. Ver docs/fase-4/4.11-CONCURRENCIA.md
A33: T-28 | B33: Resuelta | D33: RESUELTA (2026-08-25). El paso verificar-pantallas.py del CI estaba roto desde que se instalo el workflow. — Apuntaba a stage/routes/web.php y stage/app, que es la disposicion del area de entrega y no la del repositorio: reventaba con un FileNotFoundError sobre una carpeta que en la maquina no existe. | E33: — | F33: Equipo de desarrollo | G33: No salia verde en falso --eso habria sido peor-- pero el paso no comprobaba nada y el mensaje no decia nada util. Las dos herramientas resuelven ahora la disposicion mirando cual existe. Y la puerta nueva sale con codigo 2 si recorre CERO archivos: contar que no hay problemas cuando lo que no hay es busqueda es el modo de fallo mas caro de una comprobacion automatica, y con este van tres en dos dias (T-25, la regex de verificar-fixturas.py, y esta)
A34: T-30 | B34: Resuelta | D34: RESUELTA (2026-08-25). — 09-NEXT-ITERATION.md llevaba desde el 21 de agosto diciendo «me detengo aqui; no hay codigo, no hay esquema y no hay wireframes». | E34: — | F34: Equipo de desarrollo | G34: Cuatro dias y 64 tablas despues, el documento cuyo unico trabajo es decir que viene ahora describia un proyecto que ya no existe. Reescrito entero: estado medido, que bloquea y a quien le toca, y la siguiente iteracion propuesta con su motivo. Y tres tareas mas estaban en el mismo estado: T-11, T-15 y T-16 decian «hecho en 3.14 / 3.11 / 3.12» y llevaban el marcador de ABIERTA. Es el mismo defecto que dejo T-12 en 📋 durante un mes estando resuelta
A35: T-31 | B35: Resuelta | D35: RESUELTA (2026-08-25). Dos de las seis puertas no se podian ejecutar del lado del contenedor, y por eso se entrego codigo con tres errores de PHPStan. — PHPStan y Deptrac no estaban instalados: packagist esta bloqueado desde aqui, asi que durante toda la sesion esas dos salieron «sin comprobar» mientras las otras cuatro pasaban. | E35: — | F35: Equipo de desarrollo | G35: Se resolvio trayendo los .phar por el puente desde la maquina del usuario --phpstan.phar (27 MB), deptrac.phar (1,5 MB), larastan y sus dependencias--, mas phpstan.neon y deptrac.yaml. Costo un rato: la limpieza de rutas colgantes del autoloader de T-25 habia dejado la entrada PSR-4 de Larastan con el array VACIO, y en PHP la ultima definicion de una clave gana, asi que rellenarla arriba no servia de nada --habia que rellenar la duplicada de abajo--. Es el mismo arreglo mordiendose la cola dos iteraciones despues. Ahora puertas corre las seis aqui. Las seis, en verde
A36: T-32 | B36: Resuelta | D36: RESUELTA (2026-08-25). — Los tres errores que PHPStan encontro en la maquina del usuario. | E36: — | F36: Equipo de desarrollo | G36: Dos eran de tipos puros --collect() sobre un mixed, y Collection<int, object> donde llega Collection<int, stdClass>, que no vale porque TValue no es covariante--. El tercero escondia un defecto de negocio: $antes salia de pluck() sin castear y $despues ya venia en int, asi que ['1'] !== [1] era SIEMPRE cierto y la bitacora anotaria un cambio de categorias cada vez que se guarda una marca, haya cambiado o no. No se pudo reproducir: depende de si PDO devuelve cadenas o enteros, y en el contenedor devuelve enteros. Queda fijado por MarcasTest, que documenta la intencion y dice explicitamente que no demuestra el fallo
A37: T-33 | B37: Resuelta | D37: RESUELTA (2026-08-25, iteracion 7.3). — ck_creq_deadline y ck_creq_permanence. | E37: — | F37: Equipo de desarrollo | G37: Los acotaba solo GuardarRequisitoRequest, y permanence_days es «cuanto debe seguir publicado»: de ahi sale lo que se le exige al creador y lo que se le promete al cliente. Un 100.000 --273 anos-- entraba por cualquier importacion, y lo que se rompe no es la base sino un acuerdo que nadie puede cumplir
A38: T-36 | B38: Resuelta | D38: RESUELTA (2026-08-26, iteracion 7.6b). — Ver DEC-126. | E38: — | F38: Equipo de desarrollo | G38: La pieza ya estaba: Cuentas::paraCreador() y Cuentas::paraInterno() se diferencian en tres argumentos, y eso es lo que se cobro la decision de 5.9 de poner esa clase en Identity en vez de en Creator
... A71: T-77 | B71: Resuelta | D71: RESUELTA (2026-08-31, hotfix de 9.12). El sembrador reescribia lo que una persona ya habia configurado, y ademas reventaba. | E71: 9.12 (hotfix) | F71: Equipo de desarrollo | G71: Reportada desde la instalacion: db:seed se paro con un 45000 porque updateOrInsert movia el valid_from de la fila ABIERTA de fx_official_sources encima de un periodo cerrado a mano (T-73 desde el otro lado). Lo que el error tapaba era peor: el sembrador murio en la linea 71 de 700, asi que los proveedores de 9.17d y los tipos de comprobante de 9.12 no llegaron a entrar. Y de fondo: cada db:seed --lo que el runbook manda tras cada migracion-- devolvia a fabrica el nombre, lema, colores y tipografia de la marca y la direccion de la sociedad, REGENERABA sus uuid y reactivaba fuentes y proveedores apagados a proposito. Regla nueva: lo que una persona puede cambiar se siembra si falta y no se toca si esta (sembrarSiFalta); donde hay vigencia, el periodo empieza el dia siguiente al ultimo cierre. 5 pruebas verificadas en rojo sin el arreglo.
A72: T-78 | B72: Abierta | C72: Media | D72: Convertir a route() las 390 direcciones escritas a mano en las pruebas. | E72: Al tocar cada archivo | F72: Equipo de desarrollo | G72: La mudanza a /backoffice fue gratis en la aplicacion --ni una URL a mano-- y costo 390 sustituciones en tests/, porque una prueba que escribe /clientes FIJA la URL. Se corrigieron con un guion que sale de la lista real de rutas movidas, y la primera pasada dejo dos fuera (/bitacora?tipo=..., con cadena de consulta) que cazo la suite. Mientras sigan siendo cadenas, la proxima mudanza costara lo mismo.

Sheet Preguntas
A1: Preguntas de negocio (Q-XX). Una pregunta abierta es trabajo que NO se puede hacer hasta que alguien decida. Las respondidas conservan la pregunta original detrás de la respuesta. Fuente: docs/05-DECISION-LOG.md.
A2: ID | B2: Estado | C2: Prioridad | D2: Que hay que decidir | E2: Cuando hace falta | F2: Quien la desbloquea | G2: Detalle
A3: Q-47 | B3: Abierta | D3: Abierto por la iteración 3.6. | E3: Iteración de rechazo de creadores | F3: Tu (decision de negocio) | G3: BR-CREATOR-014 fija un periodo de gracia de 30 días antes de rechazar a un creador por falta de datos fiscales, y dice «configurable». ¿Configurable globalmente (una constante de despliegue) o por creador, como payment_term_days? No lo invento: son dos modelos de datos distintos. Hasta que se responda, el periodo de gracia no está implementado
A4: Q-50 | B4: Abierta | D4: ¿campaign_creators, agreement_amendments, domain_events y status_transitions son evidencia? | E4: Al construir el módulo de campañas | F4: Tu (decision de negocio) | G4: Se quedaron fuera de 3.12 a propósito. campaign_creators lleva agreed_amount —el precio pactado, congelado—, y borrar una participación borraría el precio con ella; pero el módulo de campañas no está construido y decidir ahora si una participación se borra o se cancela sería adivinar. Los otros dos son rastros de auditoría de alto volumen, donde puede hacer falta purga por antigüedad. Que lo decida la iteración que los construya, con el caso de uso delante
A5: Q-52 | B5: Abierta | D5: ¿Un cliente debería exigir contacto principal de facturación antes de poder estar active? | E5: Facturación (F9) | F5: Tu (decision de negocio) | G5: Hoy nada lo obliga: contacts no tiene regla que exija un principal de ningún tipo, y un cliente puede activarse sin un solo contacto. Cuando llegue la facturación habrá que saber a quién se le manda la factura, y descubrirlo entonces significa perseguir clientes ya activos. La ficha lo avisa en ámbar y no lo impide, porque convertirlo en requisito es una decisión de negocio: bloquear el alta de un cliente por un dato que a veces llega después tiene su propio coste. Si la respuesta es sí, el sitio es la activación del cliente, no contacts
A6: Q-53 | B6: Abierta | D6: ¿El mismo correo repetido dentro del mismo cliente y tipo es un error? | E6: Importación de clientes | F6: Tu (decision de negocio) | G6: contact_email no es único a propósito: es un canal comercial y puede compartirse (facturacion@cliente.com para varias personas), a diferencia de users.email, que es la identidad de acceso y sí lo es. Pero dos contactos con el mismo correo, el mismo cliente y el mismo tipo parece captura duplicada más que reparto. No se ha añadido regla: una validación que solo vive en el formulario se la salta cualquier importación o INSERT de mantenimiento. Si se decide que es error, el sitio es el esquema
A7: Q-54 | B7: Abierta | D7: ¿Se puede corregir un periodo fiscal ya CERRADO? | E7: Primera correccion real de un histórico | F7: Tu (decision de negocio) | G7: DEC-078 dice que no: sólo se corrige el vigente. Cubre el caso normal —el cliente cambió de razón social, y eso es un periodo nuevo, no una reescritura— pero deja fuera el RUC tecleado mal que no se detecta hasta meses después, cuando el periodo ya se cerró. Hoy eso se arregla en base de datos. Si se decide permitirlo por pantalla, la forma es la de la anulación de perfiles fiscales de creador (3.11): permiso propio, motivo escrito y rastro de quién. Lo que no puede ser es un UPDATE normal
A8: Q-55 | B8: Abierta | D8: ¿Se valida el formato del documento fiscal por país? | E8: Alta de clientes en el segundo país | F8: Tu (decision de negocio) | G8: Hoy no: tax_id_number acepta cualquier cosa de hasta 40 caracteres y la pantalla avisa de que no se comprueba. Escribir una tabla de expresiones regulares (11 dígitos para un RUC peruano, dígito verificador del NIT colombiano…) es fácil y es una trampa: en cuanto una esté mal o falte un país, el sistema rechaza un documento válido y no hay forma de meterlo, que es peor que aceptar uno malo —eso se detecta al facturar—. Si se hace, tiene que ser dato de catálogo por país y editable, no código
A9: Q-56 | B9: Abierta | D9: .deliverable_versions es evidencia? | E9: 8.1 | F9: Tu (decision de negocio) | G9: Hoy se puede borrar fisicamente. El criterio de 3.12 para entrar en la lista de no_delete es «la fila es EVIDENCIA de algo que paso, y de ella depende dinero o una obligacion legal», y una version entregada cumple los dos: es lo que el cliente aprueba y lo que dispara el pago. Borrar la version 1 despues de aprobar la 2 reescribe la historia de una ronda de correccion que se facturo. No se ha cambiado en 8.1 porque 3.12 eligio dieciocho tablas de una lista y no hay documento que diga si esta se considero y se descarto o si simplemente no estaba (T-29): decidirlo con el documento delante, no de memoria. Nota practica si se decide que si: la suite de 8.1 dejaria de poder limpiar lo suyo, que es el caso «TOZUDAS» que verificar-fixturas.py ya documenta, y la propia suite lo dice en el sitio donde se rompera
A10: Q-57 | B10: Abierta | D10: .Donde acaba la linea del cargo por una ronda de correccion de mas? | E10: 8.3 | F10: Tu (decision de negocio) | G10: Hoy queda la DECISION en content_reviews --se cobra o se absorbe, quien lo autorizo y cuando-- y la pantalla de entregables la ensena como pendiente de facturar. No va a campaign_costs a proposito (DEC-135). Cuando exista facturacion (F9) habra que decidir si es una invoice_lines que se genera sola, un concepto aparte, o algo que finanzas teclea leyendo esta lista. Se decide con invoice_lines delante, no de memoria, y hasta entonces la lista de la pantalla es el registro
A11: Q-58 | B11: Abierta | D11: .Se puede reabrir un entregable ya PUBLICADO o VERIFICADO? | E11: 8.2 | F11: Tu (decision de negocio) | G11: Hoy no: tg_cvw_entregable_abierto cierra published, verified y cancelled sin excepcion, y solo deja reabrir lo approved. No hay diferencia practica todavia porque publications se llena en 8.6, pero cuando la haya habra que decidir que pasa con la evidencia archivada (8.7) y con la permanencia minima (8.8) de un post que se retira para rehacerlo. Se decide con publication_evidence delante
A12: Q-59 | B12: Abierta | D12: ¿La ventana de permanencia se alarga por los dias que el post estuvo caido? | E12: Con el contrato del creador | F12: Tu (decision de negocio) | G12: Hoy no: reponer devuelve la publicacion a verified y permanence_until no se toca. Si el post estuvo tres dias fuera, la marca perdio tres dias de exposicion y el creador cumple igual. Alargarla seria lo justo y alargarla por mi cuenta seria inventarme una clausula, asi que va con el texto del contrato, junto a T-09
A13: Q-60 | B13: Abierta | D13: ¿deliverables.revision_rounds_used deberia existir? | E13: Facturacion (F9) | F13: Tu contador | G13: Es una desnormalizacion que anadio 8.3. Las revisiones son append-only (tg_cvw_inmutable), asi que el numero exacto se deriva con un COUNT(*) sobre content_reviews donde consumes_round = 1, y entonces no hay contador que desincronizar ni que proteger --tg_del_rondas sobraria--. A cambio, cada lectura del techo cuesta un JOIN. Se decide cuando ese numero sea una linea de factura
A14: Q-61 | B14: Abierta | D14: ¿Como se marca una ronda de mas como facturada? | E14: Facturacion (F9) | F14: Tu (decision de negocio) | G14: content_reviews es append-only desde 8.3 --tg_cvw_inmutable bloquea todo UPDATE-- asi que no se le puede poner un invoiced_at. El enlace tiene que ir al reves: de la linea de factura a la revision. Mientras no exista, rondasCobrables() devuelve todas las autorizadas y la pantalla lo dice con esas palabras. Lo decide quien construya la facturacion, que es quien sabe que forma tiene una linea
... A37: Q-21 | B37: Resuelta | D37: RESPONDIDA (2026-08-30). | E37: Respondida | F37: Tu contador | G37: Resuelta por Q-03: no hay proveedor intermedio, se timbra directo con SUNAT y todo es configurable. *Pregunta original:* ¿El proveedor de facturación electrónica permite una cuenta por sociedad, o exige contrato separado por RUC?
A38: Q-22 | B38: Resuelta | D38: 100% interna | E38: — | F38: Tu (decision de negocio)
A39: Q-23 | B39: Resuelta | D39: RESPONDIDA (2026-08-30). | E39: Respondida | F39: Tu (decision de negocio) | G39: La gamificacion premia con reconocimiento. *Pregunta original:* ¿Qué desbloquea realmente el nivel? Define si la gamificación es reconocimiento o política comercial.
A40: Q-24 | B40: Resuelta | D40: RESPONDIDA (2026-08-30). | E40: Respondida | F40: Tu (decision de negocio) | G40: Por ahora no hay premios en dinero. Habra un catalogo de premios canjeables con XP --viajes, cosas-- configurable desde el admin. Ver DEC-194. *Pregunta original:* ¿El XP podrá convertirse en dinero o bienes? Si no, el problema fiscal y legal se reduce drásticamente.
A41: Q-25 | B41: Resuelta | D41: RESPONDIDA (2026-08-30). | E41: Respondida | F41: Tu (decision de negocio) | G41: El hito de consolidacion del referido es la primera campana completada. *Pregunta original:* ¿Cuál es el hito de consolidación del referido: aprobación, o primera campaña completada?
A42: Q-26 | B42: Resuelta | D42: RESPONDIDA (2026-08-30). | E42: Respondida | F42: Tu (decision de negocio) | G42: Absorbida por Q-24: los retos internos premian con XP canjeable en el catalogo, no con dinero. *Pregunta original:* ¿Los retos internos pagarán en dinero, producto o acceso prioritario?
A43: Q-27 | B43: Resuelta | D43: RESPONDIDA (2026-08-30). La Academia del creador QUEDA | E43: Respondida | F43: Tu (decision de negocio) | G43: , y cada modulo es configurable desde el admin. Ver DEC-196. *Pregunta original:* ¿Hay presupuesto para la Academia del creador? Es contenido, no software.
A44: Q-29 | B44: Resuelta | D44: RESPONDIDA (2026-08-30). | E44: Respondida | F44: Tu (marca) | G44: La tipografia y la identidad visual se configuran desde el admin, no se eligen en el codigo. La propuesta (Sora + Plus Jakarta Sans + IBM Plex Mono) queda como valor de partida y se cambia sin tocar codigo (DEC-190). *Pregunta original:* ¿Se aprueba la propuesta tipográfica (Sora + Plus Jakarta Sans + IBM Plex Mono), o hay una tipografía corporativa ya comprada?
A45: Q-30 | B45: Resuelta | D45: RESPONDIDA (2026-08-30). | E45: Respondida | F45: Tu (marca) | G45: El kit de marca si esta en el repositorio (marca/), pero al mirarlo para contestar salio algo que conviene saber: el logotipo horizontal y el vertical llevan el texto vivo con font-family="DejaVu Sans" --una tipografia de sistema, no una elegida-- y los derivados de public/img/brand/ son los contornos de esa misma. No hay un maestro editable con tipografia de diseno. La respuesta es la correcta: se hace configurable y se sube desde el admin cuando exista uno de verdad. Ver T-71. *Pregunta original:* ¿Existe versión editable del wordmark (AI/Figma) con la tipografía real que usó el diseñador? Si la hay, sustituye a mis contornos.
A46: Q-31 | B46: Resuelta | D46: RESPONDIDA (2026-08-30). | E46: Respondida | F46: Tu (decision de negocio) | G46: Configurable desde el admin: la marca de la plataforma es un dato, no un archivo del repositorio. *Pregunta original:* ¿Se sustituye el kit original por las versiones corregidas, o conviven? Recomiendo sustituir: dos favicon distintos garantizan que alguien use el roto.
A47: Q-33 | B47: Resuelta | D47: RESUELTA (negocio, 2026-08-22): — todo creador debe tener datos fiscales legales y vigentes. | E47: — | F47: Tu (decision de negocio) | G47: No hay pago informal. Sin ellos no se activa; si no se regulariza, se rechaza. → BR-CREATOR-013
A48: Q-34 | B48: Resuelta | D48: RESPONDIDA (2026-08-30). | E48: Respondida | F48: Tu (decision de negocio) | G48: Colombia no es prioritaria en esta primera fase. *Pregunta original:* ⚠️ ADOPTADA MI RECOMENDACIÓN, contraria a lo que dijiste — revísala. Dijiste *"DIAN directo"*. Recomiendo empezar con un proveedor tecnológico certificado y dejar la habilitación propia para después. Motivo: habilitarse como proveedor propio ante la DIAN es un proceso de meses con pruebas de conformidad, y bloquearía la operación en Colombia mientras tanto. Con proveedor se factura en semanas y la habilitación propia se hace en paralelo sin urgencia. Si tu prioridad es no depender de terceros, dilo y lo revierto
A49: Q-35 | B49: Resuelta | D49: ADOPTADA (recomendación, 2026-08-22): | E49: — | F49: Tu (decision de negocio) | G49: el cliente asume producto y logística, y ambos se registran como *Direct Cost* de la campaña e impactan el margen (BR-FIN-011, que ya lo decía). El creador asume el costo de creación, no el del producto — eso ya lo confirmaste. El producto no se devuelve salvo pacto expreso en la campaña
A50: Q-36 | B50: Resuelta | D50: RESUELTA (negocio, 2026-08-22): — todo por Google Workspace por ahora — el volumen actual no llega a 100 correos. | E50: Configuración | F50: Tu (decision de negocio) | G50: El proveedor transaccional queda como opción de configuración, no como código nuevo: el correo es una conexión de integración con purpose = transactional_mail (docs/12), así que cambiarlo es editar una conexión en el back-office. Disparador para cambiar, escrito ahora para no discutirlo luego: cuando un solo envío de campaña supere ~200 destinatarios en un día, o cuando empiecen a salir avisos de pago. Ver docs/fase-2/2.10 §8
... A60: Q-63 | B60: Resuelta | D60: RESPONDIDA (2026-08-30). | E60: Respondida | F60: Tu contador | G60: NO se fija un lado del tipo de cambio en el codigo: se configura desde el admin, y por tipo de transaccion --lo que se paga a un creador, lo que se le cobra a un cliente, un gasto-- porque no tienen por que usar el mismo. Ver DEC-195. *Pregunta original:* 🔴 .Que LADO del tipo de cambio se aplica a cada operacion: compra, venta o media? SUNAT publica los dos y 9.1 los guarda separados (side), sin valor por defecto a proposito, para que nadie lo elija sin querer (DEC-159). Es una decision contable y no tecnica: cada eleccion da un margen distinto para los mismos hechos, y el dia que se elija cambian todos los margenes historicos a la vez. Bloquea de verdad: 9.10a y 9.10 agrupan por moneda en vez de sumar por esto (DEC-180), y la rentabilidad no da porcentaje cuando hay dos monedas (DEC-185). Se abrio en 9.1 y esta fila nace en 9.15

Sheet Decisiones
